Workbook

Sheet Huong Dan
A1: HƯỚNG DẪN SỬ DỤNG & TÁI SỬ DỤNG TEMPLATE CONTENT CALENDAR ĐA NGÀNH
A3: 0. FILE NÀY LÀ TEMPLATE TRỐNG — chưa có nội dung cluster mẫu nào:
A4: - Tất cả sheet Pillar (và Tuan Buffer) hiện KHÔNG có dòng dữ liệu nào — chỉ có cấu trúc cột, header,
A5: dropdown (Loại 3H/Kênh/Trạng thái/Phễu), công thức Tuần/Deadline, và định dạng màu theo trạng thái.
A6: - Content Calendar và Dashboard vẫn hiển thị đúng lưới/công thức nhưng sẽ trống/= 0 cho tới khi bạn điền dữ liệu.
A7: - Cách thêm nội dung thật (khuyến nghị — KHÔNG cần chạy lại script): mở sheet Pillar tương ứng, điền trực tiếp
A8: vào các cột: Mã Cluster, Tên bài/Chủ đề, Loại 3H (chọn từ dropdown), Mục tiêu phễu, Persona, Từ khóa, Tone,
A9: Độ dài, Outline, CTA, Kênh (dropdown), Ngày đăng (chọn ngày — cột 'Tuần (auto)' và 'Deadline' tự tính),
A10: Người phụ trách, Trạng thái (dropdown), KPI dự kiến. Content Calendar sẽ tự hiển thị ngay khi Excel tính lại.
A11: - Cách thêm nội dung bằng script (khi cần tạo lại file từ đầu với dữ liệu khác): điền dữ liệu vào
A12: PILLAR_DATA_RAW ở đầu file generate-content-calendar.py theo đúng khóa từng Pillar, rồi chạy lại script —
A13: ngày đăng và vị trí buffer sẽ được TỰ ĐỘNG tính toán và phân bổ xen kẽ (xem mục 5).
... A80: Bảng ví dụ (17 trường của 1 dòng cluster mẫu):
A81: Trường (cột trong sheet Pillar) | B81: Giá trị ví dụ minh họa | C81: Giải thích
A82: Mã Cluster | B82: P1-01 | C82: Mã tự đặt để dễ tra cứu, gợi ý: <tên Pillar>-<số thứ tự>.
A83: Tên bài/Chủ đề | B83: 5 dấu hiệu nhận biết [sản phẩm] không đạt chuẩn chất lượng | C83: Tên bài viết/nội dung cụ thể, nên chứa từ khóa chính.
A84: Loại 3H | B84: Hygiene | C84: Chọn 1 trong 3: Hero (hiếm, đầu tư cao) / Hub (định kỳ) / Hygiene (liên tục, SEO).
A85: Mục tiêu phễu | B85: TOFU | C85: TOFU (nhận biết) / MOFU (cân nhắc) / BOFU (quyết định mua).
A86: Persona mục tiêu | B86: [Điền persona chính đã xây dựng ở Module 2] | C86: Đối tượng cụ thể bài viết hướng tới.
A87: Từ khóa chính | B87: cách nhận biết [sản phẩm] kém chất lượng, mẹo chọn [sản phẩm] | C87: Từ khóa SEO chính + 1-2 từ khóa dài liên quan.
A88: Tone giọng điệu | B88: Gần gũi, đáng tin cậy, có dẫn chứng cụ thể | C88: Văn phong khi viết, khớp với Brand Voice đã định nghĩa.
A89: Độ dài mong muốn | B89: 600-800 từ | C89: Ước lượng độ dài bài viết hoặc thời lượng video.
A90: Outline/Dàn ý chính | B90: Hook mở bài -> 5 dấu hiệu nhận biết (mỗi dấu hiệu 1 đoạn) -> Lời khuyên/CTA | C90: Dàn ý ngắn gọn để người viết bám theo, tránh lệch trọng tâm.
A91: CTA mong muốn | B91: Lưu bài để tham khảo khi mua hàng lần tới | C91: Hành động cụ thể muốn người đọc thực hiện.
A92: Kênh đăng | B92: Facebook | C92: Chọn từ dropdown: Facebook/Zalo OA/Website/TikTok/Email (tùy Config).
... A98: KPI dự kiến | B98: Organic traffic; Time on page > 1'30" | C98: Chỉ số đo hiệu quả, nên khác nhau theo từng loại 3H (xem mục 6).

Sheet Content Calendar
A1: ="CONTENT CALENDAR THÁNG "&Config!$B$8&"/"&Config!$B$7&" — "&Config!$B$5&" (liên kết động với sheet Pillar)"
A2: Tuần / Pillar | B2: Thứ 2 | C2: Thứ 3 | D2: Thứ 4 | E2: Thứ 5 | F2: Thứ 6 | G2: Thứ 7 | H2: CN
A3: TUẦN 1 P1: [Điền tên chủ đề Pillar 1] | C3: 1 | D3: 2 | E3: 3 | F3: 4 | G3: 5 | H3: 6 | S3: 46266 | AA3: 46267 | AI3: 46268 | AQ3: 46269 | AY3: 46270 | BG3: 46271
C4: =IF($Y$4="",TRIM($T$4&$U$4&$V$4&$W$4&$X$4),HYPERLINK("#"&$Z$4,TRIM($T$4&$U$4&$V$4&$W$4&$X$4))) | D4: =IF($AG$4="",TRIM($AB$4&$AC$4&$AD$4&$AE$4&$AF$4),HYPERLINK("#"&$AH$4,TRIM($AB$4&$AC$4&$AD$4&$AE$4&$AF$4))) | E4: =IF($AO$4="",TRIM($AJ$4&$AK$4&$AL$4&$AM$4&$AN$4),HYPERLINK("#"&$AP$4,TRIM($AJ$4&$AK$4&$AL$4&$AM$4&$AN$4))) | F4: =IF($AW$4="",TRIM($AR$4&$AS$4&$AT$4&$AU$4&$AV$4),HYPERLINK("#"&$AX$4,TRIM($AR$4&$AS$4&$AT$4&$AU$4&$AV$4))) | G4: =IF($BE$4="",TRIM($AZ$4&$BA$4&$BB$4&$BC$4&$BD$4),HYPERLINK("#"&$BF$4,TRIM($AZ$4&$BA$4&$BB$4&$BC$4&$BD$4))) | H4: =IF($BM$4="",TRIM($BH$4&$BI$4&$BJ$4&$BK$4&$BL$4),HYPERLINK("#"&$BN$4,TRIM($BH$4&$BI$4&$BJ$4&$BK$4&$BL$4))) | T4: {=_xlfn.TEXTJOIN("",TRUE,IF('Pillar 1'!$L$5:$L$104=$S$3,"["&'Pillar 1'!$C$5:$C$104&"] "&'Pillar 1'!$B$5:$B$104&CHAR(10),""))} | U4: {=_xlfn.TEXTJOIN("",TRUE,IF('Pillar 2'!$L$5:$L$104=$S$3,"["&'Pillar 2'!$C$5:$C$104&"] "&'Pillar 2'!$B$5:$B$104&CHAR(10),""))} | V4: {=_xlfn.TEXTJOIN("",TRUE,IF('Pillar 3'!$L$5:$L$104=$S$3,"["&'Pillar 3'!$C$5:$C$104&"] "&'Pillar 3'!$B$5:$B$104&CHAR(10),""))} | W4: {=_xlfn.TEXTJOIN("",TRUE,IF('Pillar 4'!$L$5:$L$104=$S$3,"["&'Pillar 4'!$C$5:$C$104&"] "&'Pillar 4'!$B$5:$B$104&CHAR(10),""))} | X4: {=_xlfn.TEXTJOIN("",TRUE,IF('Tuan Buffer'!$L$5:$L$104=$S$3,"["&'Tuan Buffer'!$C$5:$C$104&"] "&'Tuan Buffer'!$B$5:$B$104&CHAR(10),""))} | Y4: =IF(IFERROR(INDEX('Pillar 1'!$C$5:$C$104,MATCH($S$3,'Pillar 1'!$L$5:$L$104,0)),"")<>"",IFERROR(INDEX('Pillar 1'!$C$5:$C$104,MATCH($S$3,'Pillar 1'!$L$5:$L$104,0)),""),IF(IFERROR(INDEX('Pillar 2'!$C$5:$C$104,MATCH($S$3,'Pillar 2'!$L$5:$L$104,0)),"")<>"",IFERROR(INDEX('Pillar 2'!$C$5:$C$104,MATCH($S$3,'Pillar 2'!$L$5:$L$104,0)),""),IF(IFERROR(INDEX('Pillar 3'!$C$5:$C$104,MATCH($S$3,'Pillar 3'!$L$5:$L$104,0)),"")<>"",IFERROR(INDEX('Pillar 3'!$C$5:$C$104,MATCH($S$3,'Pillar 3'!$L$5:$L$104,0)),""),IF(IFERROR(INDEX('Pillar 4'!$C$5:$C$104,MATCH($S$3,'Pillar 4'!$L$5:$L$104,0)),"")<>"",IFERROR(INDEX('Pillar 4'!$C$5:$C$104,MATCH($S$3,'Pillar 4'!$L$5:$L$104,0)),""),IFERROR(INDEX('Tuan Buffer'!$C$5:$C$104,MATCH($S$3,'Tuan Buffer'!$L$5:$L$104,0)),""))))) | Z4: =IF(IFERROR(INDEX('Pillar 1'!$C$5:$C$104,MATCH($S$3,'Pillar 1'!$L$5:$L$104,0)),"")<>"","'Pillar 1'!A"&IFERROR(MATCH($S$3,'Pillar 1'!$L$5:$L$104,0)+5-1,0),IF(IFERROR(INDEX('Pillar 2'!$C$5:$C$104,MATCH($S$3,'Pillar 2'!$L$5:$L$104,0)),"")<>"","'Pillar 2'!A"&IFERROR(MATCH($S$3,'Pillar 2'!$L$5:$L$104,0)+5-1,0),IF(IFERROR(INDEX('Pillar 3'!$C$5:$C$104,MATCH($S$3,'Pillar 3'!$L$5:$L$104,0)),"")<>"","'Pillar 3'!A"&IFERROR(MATCH($S$3,'Pillar 3'!$L$5:$L$104,0)+5-1,0),IF(IFERROR(INDEX('Pillar 4'!$C$5:$C$104,MATCH($S$3,'Pillar 4'!$L$5:$L$104,0)),"")<>"","'Pillar 4'!A"&IFERROR(MATCH($S$3,'Pillar 4'!$L$5:$L$104,0)+5-1,0),"'Tuan Buffer'!A"&IFERROR(MATCH($S$3,'Tuan Buffer'!$L$5:$L$104,0)+5-1,0))))) | AB4: {=_xlfn.TEXTJOIN("",TRUE,IF('Pillar 1'!$L$5:$L$104=$AA$3,"["&'Pillar 1'!$C$5:$C$104&"] "&'Pillar 1'!$B$5:$B$104&CHAR(10),""))} | AC4: {=_xlfn.TEXTJOIN("",TRUE,IF('Pillar 2'!$L$5:$L$104=$AA$3,"["&'Pillar 2'!$C$5:$C$104&"] "&'Pillar 2'!$B$5:$B$104&CHAR(10),""))} | AD4: {=_xlfn.TEXTJOIN("",TRUE,IF('Pillar 3'!$L$5:$L$104=$AA$3,"["&'Pillar 3'!$C$5:$C$104&"] "&'Pillar 3'!$B$5:$B$104&CHAR(10),""))} | AE4: {=_xlfn.TEXTJOIN("",TRUE,IF('Pillar 4'!$L$5:$L$104=$AA$3,"["&'Pillar 4'!$C$5:$C$104&"] "&'Pillar 4'!$B$5:$B$104&CHAR(10),""))} | AF4: {=_xlfn.TEXTJOIN("",TRUE,IF('Tuan Buffer'!$L$5:$L$104=$AA$3,"["&'Tuan Buffer'!$C$5:$C$104&"] "&'Tuan Buffer'!$B$5:$B$104&CHAR(10),""))} | AG4: =IF(IFERROR(INDEX('Pillar 1'!$C$5:$C$104,MATCH($AA$3,'Pillar 1'!$L$5:$L$104,0)),"")<>"",IFERROR(INDEX('Pillar 1'!$C$5:$C$104,MATCH($AA$3,'Pillar 1'!$L$5:$L$104,0)),""),IF(IFERROR(INDEX('Pillar 2'!$C$5:$C$104,MATCH($AA$3,'Pillar 2'!$L$5:$L$104,0)),"")<>"",IFERROR(INDEX('Pillar 2'!$C$5:$C$104,MATCH($AA$3,'Pillar 2'!$L$5:$L$104,0)),""),IF(IFERROR(INDEX('Pillar 3'!$C$5:$C$104,MATCH($AA$3,'Pillar 3'!$L$5:$L$104,0)),"")<>"",IFERROR(INDEX('Pillar 3'!$C$5:$C$104,MATCH($AA$3,'Pillar 3'!$L$5:$L$104,0)),""),IF(IFERROR(INDEX('Pillar 4'!$C$5:$C$104,MATCH($AA$3,'Pillar 4'!$L$5:$L$104,0)),"")<>"",IFERROR(INDEX('Pillar 4'!$C$5:$C$104,MATCH($AA$3,'Pillar 4'!$L$5:$L$104,0)),""),IFERROR(INDEX('Tuan Buffer'!$C$5:$C$104,MATCH($AA$3,'Tuan Buffer'!$L$5:$L$104,0)),""))))) | AH4: =IF(IFERROR(INDEX('Pillar 1'!$C$5:$C$104,MATCH($AA$3,'Pillar 1'!$L$5:$L$104,0)),"")<>"","'Pillar 1'!A"&IFERROR(MATCH($AA$3,'Pillar 1'!$L$5:$L$104,0)+5-1,0),IF(IFERROR(INDEX('Pillar 2'!$C$5:$C$104,MATCH($AA$3,'Pillar 2'!$L$5:$L$104,0)),"")<>"","'Pillar 2'!A"&IFERROR(MATCH($AA$3,'Pillar 2'!$L$5:$L$104,0)+5-1,0),IF(IFERROR(INDEX('Pillar 3'!$C$5:$C$104,MATCH($AA$3,'Pillar 3'!$L$5:$L$104,0)),"")<>"","'Pillar 3'!A"&IFERROR(MATCH($AA$3,'Pillar 3'!$L$5:$L$104,0)+5-1,0),IF(IFERROR(INDEX('Pillar 4'!$C$5:$C$104,MATCH($AA$3,'Pillar 4'!$L$5:$L$104,0)),"")<>"","'Pillar 4'!A"&IFERROR(MATCH($AA$3,'Pillar 4'!$L$5:$L$104,0)+5-1,0),"'Tuan Buffer'!A"&IFERROR(MATCH($AA$3,'Tuan Buffer'!$L$5:$L$104,0)+5-1,0))))) | AJ4: {=_xlfn.TEXTJOIN("",TRUE,IF('Pillar 1'!$L$5:$L$104=$AI$3,"["&'Pillar 1'!$C$5:$C$104&"] "&'Pillar 1'!$B$5:$B$104&CHAR(10),""))} | AK4: {=_xlfn.TEXTJOIN("",TRUE,IF('Pillar 2'!$L$5:$L$104=$AI$3,"["&'Pillar 2'!$C$5:$C$104&"] "&'Pillar 2'!$B$5:$B$104&CHAR(10),""))} | AL4: {=_xlfn.TEXTJOIN("",TRUE,IF('Pillar 3'!$L$5:$L$104=$AI$3,"["&'Pillar 3'!$C$5:$C$104&"] "&'Pillar 3'!$B$5:$B$104&CHAR(10),""))} | AM4: {=_xlfn.TEXTJOIN("",TRUE,IF('Pillar 4'!$L$5:$L$104=$AI$3,"["&'Pillar 4'!$C$5:$C$104&"] "&'Pillar 4'!$B$5:$B$104&CHAR(10),""))} | AN4: {=_xlfn.TEXTJOIN("",TRUE,IF('Tuan Buffer'!$L$5:$L$104=$AI$3,"["&'Tuan Buffer'!$C$5:$C$104&"] "&'Tuan Buffer'!$B$5:$B$104&CHAR(10),""))} | AO4: =IF(IFERROR(INDEX('Pillar 1'!$C$5:$C$104,MATCH($AI$3,'Pillar 1'!$L$5:$L$104,0)),"")<>"",IFERROR(INDEX('Pillar 1'!$C$5:$C$104,MATCH($AI$3,'Pillar 1'!$L$5:$L$104,0)),""),IF(IFERROR(INDEX('Pillar 2'!$C$5:$C$104,MATCH($AI$3,'Pillar 2'!$L$5:$L$104,0)),"")<>"",IFERROR(INDEX('Pillar 2'!$C$5:$C$104,MATCH($AI$3,'Pillar 2'!$L$5:$L$104,0)),""),IF(IFERROR(INDEX('Pillar 3'!$C$5:$C$104,MATCH($AI$3,'Pillar 3'!$L$5:$L$104,0)),"")<>"",IFERROR(INDEX('Pillar 3'!$C$5:$C$104,MATCH($AI$3,'Pillar 3'!$L$5:$L$104,0)),""),IF(IFERROR(INDEX('Pillar 4'!$C$5:$C$104,MATCH($AI$3,'Pillar 4'!$L$5:$L$104,0)),"")<>"",IFERROR(INDEX('Pillar 4'!$C$5:$C$104,MATCH($AI$3,'Pillar 4'!$L$5:$L$104,0)),""),IFERROR(INDEX('Tuan Buffer'!$C$5:$C$104,MATCH($AI$3,'Tuan Buffer'!$L$5:$L$104,0)),""))))) | AP4: =IF(IFERROR(INDEX('Pillar 1'!$C$5:$C$104,MATCH($AI$3,'Pillar 1'!$L$5:$L$104,0)),"")<>"","'Pillar 1'!A"&IFERROR(MATCH($AI$3,'Pillar 1'!$L$5:$L$104,0)+5-1,0),IF(IFERROR(INDEX('Pillar 2'!$C$5:$C$104,MATCH($AI$3,'Pillar 2'!$L$5:$L$104,0)),"")<>"","'Pillar 2'!A"&IFERROR(MATCH($AI$3,'Pillar 2'!$L$5:$L$104,0)+5-1,0),IF(IFERROR(INDEX('Pillar 3'!$C$5:$C$104,MATCH($AI$3,'Pillar 3'!$L$5:$L$104,0)),"")<>"","'Pillar 3'!A"&IFERROR(MATCH($AI$3,'Pillar 3'!$L$5:$L$104,0)+5-1,0),IF(IFERROR(INDEX('Pillar 4'!$C$5:$C$104,MATCH($AI$3,'Pillar 4'!$L$5:$L$104,0)),"")<>"","'Pillar 4'!A"&IFERROR(MATCH($AI$3,'Pillar 4'!$L$5:$L$104,0)+5-1,0),"'Tuan Buffer'!A"&IFERROR(MATCH($AI$3,'Tuan Buffer'!$L$5:$L$104,0)+5-1,0))))) | AR4: {=_xlfn.TEXTJOIN("",TRUE,IF('Pillar 1'!$L$5:$L$104=$AQ$3,"["&'Pillar 1'!$C$5:$C$104&"] "&'Pillar 1'!$B$5:$B$104&CHAR(10),""))} | AS4: {=_xlfn.TEXTJOIN("",TRUE,IF('Pillar 2'!$L$5:$L$104=$AQ$3,"["&'Pillar 2'!$C$5:$C$104&"] "&'Pillar 2'!$B$5:$B$104&CHAR(10),""))} | AT4: {=_xlfn.TEXTJOIN("",TRUE,IF('Pillar 3'!$L$5:$L$104=$AQ$3,"["&'Pillar 3'!$C$5:$C$104&"] "&'Pillar 3'!$B$5:$B$104&CHAR(10),""))} | AU4: {=_xlfn.TEXTJOIN("",TRUE,IF('Pillar 4'!$L$5:$L$104=$AQ$3,"["&'Pillar 4'!$C$5:$C$104&"] "&'Pillar 4'!$B$5:$B$104&CHAR(10),""))} | AV4: {=_xlfn.TEXTJOIN("",TRUE,IF('Tuan Buffer'!$L$5:$L$104=$AQ$3,"["&'Tuan Buffer'!$C$5:$C$104&"] "&'Tuan Buffer'!$B$5:$B$104&CHAR(10),""))} | AW4: =IF(IFERROR(INDEX('Pillar 1'!$C$5:$C$104,MATCH($AQ$3,'Pillar 1'!$L$5:$L$104,0)),"")<>"",IFERROR(INDEX('Pillar 1'!$C$5:$C$104,MATCH($AQ$3,'Pillar 1'!$L$5:$L$104,0)),""),IF(IFERROR(INDEX('Pillar 2'!$C$5:$C$104,MATCH($AQ$3,'Pillar 2'!$L$5:$L$104,0)),"")<>"",IFERROR(INDEX('Pillar 2'!$C$5:$C$104,MATCH($AQ$3,'Pillar 2'!$L$5:$L$104,0)),""),IF(IFERROR(INDEX('Pillar 3'!$C$5:$C$104,MATCH($AQ$3,'Pillar 3'!$L$5:$L$104,0)),"")<>"",IFERROR(INDEX('Pillar 3'!$C$5:$C$104,MATCH($AQ$3,'Pillar 3'!$L$5:$L$104,0)),""),IF(IFERROR(INDEX('Pillar 4'!$C$5:$C$104,MATCH($AQ$3,'Pillar 4'!$L$5:$L$104,0)),"")<>"",IFERROR(INDEX('Pillar 4'!$C$5:$C$104,MATCH($AQ$3,'Pillar 4'!$L$5:$L$104,0)),""),IFERROR(INDEX('Tuan Buffer'!$C$5:$C$104,MATCH($AQ$3,'Tuan Buffer'!$L$5:$L$104,0)),""))))) | AX4: =IF(IFERROR(INDEX('Pillar 1'!$C$5:$C$104,MATCH($AQ$3,'Pillar 1'!$L$5:$L$104,0)),"")<>"","'Pillar 1'!A"&IFERROR(MATCH($AQ$3,'Pillar 1'!$L$5:$L$104,0)+5-1,0),IF(IFERROR(INDEX('Pillar 2'!$C$5:$C$104,MATCH($AQ$3,'Pillar 2'!$L$5:$L$104,0)),"")<>"","'Pillar 2'!A"&IFERROR(MATCH($AQ$3,'Pillar 2'!$L$5:$L$104,0)+5-1,0),IF(IFERROR(INDEX('Pillar 3'!$C$5:$C$104,MATCH($AQ$3,'Pillar 3'!$L$5:$L$104,0)),"")<>"","'Pillar 3'!A"&IFERROR(MATCH($AQ$3,'Pillar 3'!$L$5:$L$104,0)+5-1,0),IF(IFERROR(INDEX('Pillar 4'!$C$5:$C$104,MATCH($AQ$3,'Pillar 4'!$L$5:$L$104,0)),"")<>"","'Pillar 4'!A"&IFERROR(MATCH($AQ$3,'Pillar 4'!$L$5:$L$104,0)+5-1,0),"'Tuan Buffer'!A"&IFERROR(MATCH($AQ$3,'Tuan Buffer'!$L$5:$L$104,0)+5-1,0))))) | AZ4: {=_xlfn.TEXTJOIN("",TRUE,IF('Pillar 1'!$L$5:$L$104=$AY$3,"["&'Pillar 1'!$C$5:$C$104&"] "&'Pillar 1'!$B$5:$B$104&CHAR(10),""))} | BA4: {=_xlfn.TEXTJOIN("",TRUE,IF('Pillar 2'!$L$5:$L$104=$AY$3,"["&'Pillar 2'!$C$5:$C$104&"] "&'Pillar 2'!$B$5:$B$104&CHAR(10),""))} | BB4: {=_xlfn.TEXTJOIN("",TRUE,IF('Pillar 3'!$L$5:$L$104=$AY$3,"["&'Pillar 3'!$C$5:$C$104&"] "&'Pillar 3'!$B$5:$B$104&CHAR(10),""))} | BC4: {=_xlfn.TEXTJOIN("",TRUE,IF('Pillar 4'!$L$5:$L$104=$AY$3,"["&'Pillar 4'!$C$5:$C$104&"] "&'Pillar 4'!$B$5:$B$104&CHAR(10),""))} | BD4: {=_xlfn.TEXTJOIN("",TRUE,IF('Tuan Buffer'!$L$5:$L$104=$AY$3,"["&'Tuan Buffer'!$C$5:$C$104&"] "&'Tuan Buffer'!$B$5:$B$104&CHAR(10),""))} | BE4: =IF(IFERROR(INDEX('Pillar 1'!$C$5:$C$104,MATCH($AY$3,'Pillar 1'!$L$5:$L$104,0)),"")<>"",IFERROR(INDEX('Pillar 1'!$C$5:$C$104,MATCH($AY$3,'Pillar 1'!$L$5:$L$104,0)),""),IF(IFERROR(INDEX('Pillar 2'!$C$5:$C$104,MATCH($AY$3,'Pillar 2'!$L$5:$L$104,0)),"")<>"",IFERROR(INDEX('Pillar 2'!$C$5:$C$104,MATCH($AY$3,'Pillar 2'!$L$5:$L$104,0)),""),IF(IFERROR(INDEX('Pillar 3'!$C$5:$C$104,MATCH($AY$3,'Pillar 3'!$L$5:$L$104,0)),"")<>"",IFERROR(INDEX('Pillar 3'!$C$5:$C$104,MATCH($AY$3,'Pillar 3'!$L$5:$L$104,0)),""),IF(IFERROR(INDEX('Pillar 4'!$C$5:$C$104,MATCH($AY$3,'Pillar 4'!$L$5:$L$104,0)),"")<>"",IFERROR(INDEX('Pillar 4'!$C$5:$C$104,MATCH($AY$3,'Pillar 4'!$L$5:$L$104,0)),""),IFERROR(INDEX('Tuan Buffer'!$C$5:$C$104,MATCH($AY$3,'Tuan Buffer'!$L$5:$L$104,0)),""))))) | BF4: =IF(IFERROR(INDEX('Pillar 1'!$C$5:$C$104,MATCH($AY$3,'Pillar 1'!$L$5:$L$104,0)),"")<>"","'Pillar 1'!A"&IFERROR(MATCH($AY$3,'Pillar 1'!$L$5:$L$104,0)+5-1,0),IF(IFERROR(INDEX('Pillar 2'!$C$5:$C$104,MATCH($AY$3,'Pillar 2'!$L$5:$L$104,0)),"")<>"","'Pillar 2'!A"&IFERROR(MATCH($AY$3,'Pillar 2'!$L$5:$L$104,0)+5-1,0),IF(IFERROR(INDEX('Pillar 3'!$C$5:$C$104,MATCH($AY$3,'Pillar 3'!$L$5:$L$104,0)),"")<>"","'Pillar 3'!A"&IFERROR(MATCH($AY$3,'Pillar 3'!$L$5:$L$104,0)+5-1,0),IF(IFERROR(INDEX('Pillar 4'!$C$5:$C$104,MATCH($AY$3,'Pillar 4'!$L$5:$L$104,0)),"")<>"","'Pillar 4'!A"&IFERROR(MATCH($AY$3,'Pillar 4'!$L$5:$L$104,0)+5-1,0),"'Tuan Buffer'!A"&IFERROR(MATCH($AY$3,'Tuan Buffer'!$L$5:$L$104,0)+5-1,0))))) | BH4: {=_xlfn.TEXTJOIN("",TRUE,IF('Pillar 1'!$L$5:$L$104=$BG$3,"["&'Pillar 1'!$C$5:$C$104&"] "&'Pillar 1'!$B$5:$B$104&CHAR(10),""))} | BI4: {=_xlfn.TEXTJOIN("",TRUE,IF('Pillar 2'!$L$5:$L$104=$BG$3,"["&'Pillar 2'!$C$5:$C$104&"] "&'Pillar 2'!$B$5:$B$104&CHAR(10),""))} | BJ4: {=_xlfn.TEXTJOIN("",TRUE,IF('Pillar 3'!$L$5:$L$104=$BG$3,"["&'Pillar 3'!$C$5:$C$104&"] "&'Pillar 3'!$B$5:$B$104&CHAR(10),""))} | BK4: {=_xlfn.TEXTJOIN("",TRUE,IF('Pillar 4'!$L$5:$L$104=$BG$3,"["&'Pillar 4'!$C$5:$C$104&"] "&'Pillar 4'!$B$5:$B$104&CHAR(10),""))} | BL4: {=_xlfn.TEXTJOIN("",TRUE,IF('Tuan Buffer'!$L$5:$L$104=$BG$3,"["&'Tuan Buffer'!$C$5:$C$104&"] "&'Tuan Buffer'!$B$5:$B$104&CHAR(10),""))} | BM4: =IF(IFERROR(INDEX('Pillar 1'!$C$5:$C$104,MATCH($BG$3,'Pillar 1'!$L$5:$L$104,0)),"")<>"",IFERROR(INDEX('Pillar 1'!$C$5:$C$104,MATCH($BG$3,'Pillar 1'!$L$5:$L$104,0)),""),IF(IFERROR(INDEX('Pillar 2'!$C$5:$C$104,MATCH($BG$3,'Pillar 2'!$L$5:$L$104,0)),"")<>"",IFERROR(INDEX('Pillar 2'!$C$5:$C$104,MATCH($BG$3,'Pillar 2'!$L$5:$L$104,0)),""),IF(IFERROR(INDEX('Pillar 3'!$C$5:$C$104,MATCH($BG$3,'Pillar 3'!$L$5:$L$104,0)),"")<>"",IFERROR(INDEX('Pillar 3'!$C$5:$C$104,MATCH($BG$3,'Pillar 3'!$L$5:$L$104,0)),""),IF(IFERROR(INDEX('Pillar 4'!$C$5:$C$104,MATCH($BG$3,'Pillar 4'!$L$5:$L$104,0)),"")<>"",IFERROR(INDEX('Pillar 4'!$C$5:$C$104,MATCH($BG$3,'Pillar 4'!$L$5:$L$104,0)),""),IFERROR(INDEX('Tuan Buffer'!$C$5:$C$104,MATCH($BG$3,'Tuan Buffer'!$L$5:$L$104,0)),""))))) | BN4: =IF(IFERROR(INDEX('Pillar 1'!$C$5:$C$104,MATCH($BG$3,'Pillar 1'!$L$5:$L$104,0)),"")<>"","'Pillar 1'!A"&IFERROR(MATCH($BG$3,'Pillar 1'!$L$5:$L$104,0)+5-1,0),IF(IFERROR(INDEX('Pillar 2'!$C$5:$C$104,MATCH($BG$3,'Pillar 2'!$L$5:$L$104,0)),"")<>"","'Pillar 2'!A"&IFERROR(MATCH($BG$3,'Pillar 2'!$L$5:$L$104,0)+5-1,0),IF(IFERROR(INDEX('Pillar 3'!$C$5:$C$104,MATCH($BG$3,'Pillar 3'!$L$5:$L$104,0)),"")<>"","'Pillar 3'!A"&IFERROR(MATCH($BG$3,'Pillar 3'!$L$5:$L$104,0)+5-1,0),IF(IFERROR(INDEX('Pillar 4'!$C$5:$C$104,MATCH($BG$3,'Pillar 4'!$L$5:$L$104,0)),"")<>"","'Pillar 4'!A"&IFERROR(MATCH($BG$3,'Pillar 4'!$L$5:$L$104,0)+5-1,0),"'Tuan Buffer'!A"&IFERROR(MATCH($BG$3,'Tuan Buffer'!$L$5:$L$104,0)+5-1,0)))))
A5: TUẦN 2 P2: [Điền tên chủ đề Pillar 2] | B5: 7 | C5: 8 | D5: 9 | E5: 10 | F5: 11 | G5: 12 | H5: 13 | K5: 46272 | S5: 46273 | AA5: 46274 | AI5: 46275 | AQ5: 46276 | AY5: 46277 | BG5: 46278
B6: =IF($Q$6="",TRIM($L$6&$M$6&$N$6&$O$6&$P$6),HYPERLINK("#"&$R$6,TRIM($L$6&$M$6&$N$6&$O$6&$P$6))) | C6: =IF($Y$6="",TRIM($T$6&$U$6&$V$6&$W$6&$X$6),HYPERLINK("#"&$Z$6,TRIM($T$6&$U$6&$V$6&$W$6&$X$6))) | D6: =IF($AG$6="",TRIM($AB$6&$AC$6&$AD$6&$AE$6&$AF$6),HYPERLINK("#"&$AH$6,TRIM($AB$6&$AC$6&$AD$6&$AE$6&$AF$6))) | E6: =IF($AO$6="",TRIM($AJ$6&$AK$6&$AL$6&$AM$6&$AN$6),HYPERLINK("#"&$AP$6,TRIM($AJ$6&$AK$6&$AL$6&$AM$6&$AN$6))) | F6: =IF($AW$6="",TRIM($AR$6&$AS$6&$AT$6&$AU$6&$AV$6),HYPERLINK("#"&$AX$6,TRIM($AR$6&$AS$6&$AT$6&$AU$6&$AV$6))) | G6: =IF($BE$6="",TRIM($AZ$6&$BA$6&$BB$6&$BC$6&$BD$6),HYPERLINK("#"&$BF$6,TRIM($AZ$6&$BA$6&$BB$6&$BC$6&$BD$6))) | H6: =IF($BM$6="",TRIM($BH$6&$BI$6&$BJ$6&$BK$6&$BL$6),HYPERLINK("#"&$BN$6,TRIM($BH$6&$BI$6&$BJ$6&$BK$6&$BL$6))) | L6: {=_xlfn.TEXTJOIN("",TRUE,IF('Pillar 1'!$L$5:$L$104=$K$5,"["&'Pillar 1'!$C$5:$C$104&"] "&'Pillar 1'!$B$5:$B$104&CHAR(10),""))} | M6: {=_xlfn.TEXTJOIN("",TRUE,IF('Pillar 2'!$L$5:$L$104=$K$5,"["&'Pillar 2'!$C$5:$C$104&"] "&'Pillar 2'!$B$5:$B$104&CHAR(10),""))} | N6: {=_xlfn.TEXTJOIN("",TRUE,IF('Pillar 3'!$L$5:$L$104=$K$5,"["&'Pillar 3'!$C$5:$C$104&"] "&'Pillar 3'!$B$5:$B$104&CHAR(10),""))} | O6: {=_xlfn.TEXTJOIN("",TRUE,IF('Pillar 4'!$L$5:$L$104=$K$5,"["&'Pillar 4'!$C$5:$C$104&"] "&'Pillar 4'!$B$5:$B$104&CHAR(10),""))} | P6: {=_xlfn.TEXTJOIN("",TRUE,IF('Tuan Buffer'!$L$5:$L$104=$K$5,"["&'Tuan Buffer'!$C$5:$C$104&"] "&'Tuan Buffer'!$B$5:$B$104&CHAR(10),""))} | Q6: =IF(IFERROR(INDEX('Pillar 1'!$C$5:$C$104,MATCH($K$5,'Pillar 1'!$L$5:$L$104,0)),"")<>"",IFERROR(INDEX('Pillar 1'!$C$5:$C$104,MATCH($K$5,'Pillar 1'!$L$5:$L$104,0)),""),IF(IFERROR(INDEX('Pillar 2'!$C$5:$C$104,MATCH($K$5,'Pillar 2'!$L$5:$L$104,0)),"")<>"",IFERROR(INDEX('Pillar 2'!$C$5:$C$104,MATCH($K$5,'Pillar 2'!$L$5:$L$104,0)),""),IF(IFERROR(INDEX('Pillar 3'!$C$5:$C$104,MATCH($K$5,'Pillar 3'!$L$5:$L$104,0)),"")<>"",IFERROR(INDEX('Pillar 3'!$C$5:$C$104,MATCH($K$5,'Pillar 3'!$L$5:$L$104,0)),""),IF(IFERROR(INDEX('Pillar 4'!$C$5:$C$104,MATCH($K$5,'Pillar 4'!$L$5:$L$104,0)),"")<>"",IFERROR(INDEX('Pillar 4'!$C$5:$C$104,MATCH($K$5,'Pillar 4'!$L$5:$L$104,0)),""),IFERROR(INDEX('Tuan Buffer'!$C$5:$C$104,MATCH($K$5,'Tuan Buffer'!$L$5:$L$104,0)),""))))) | R6: =IF(IFERROR(INDEX('Pillar 1'!$C$5:$C$104,MATCH($K$5,'Pillar 1'!$L$5:$L$104,0)),"")<>"","'Pillar 1'!A"&IFERROR(MATCH($K$5,'Pillar 1'!$L$5:$L$104,0)+5-1,0),IF(IFERROR(INDEX('Pillar 2'!$C$5:$C$104,MATCH($K$5,'Pillar 2'!$L$5:$L$104,0)),"")<>"","'Pillar 2'!A"&IFERROR(MATCH($K$5,'Pillar 2'!$L$5:$L$104,0)+5-1,0),IF(IFERROR(INDEX('Pillar 3'!$C$5:$C$104,MATCH($K$5,'Pillar 3'!$L$5:$L$104,0)),"")<>"","'Pillar 3'!A"&IFERROR(MATCH($K$5,'Pillar 3'!$L$5:$L$104,0)+5-1,0),IF(IFERROR(INDEX('Pillar 4'!$C$5:$C$104,MATCH($K$5,'Pillar 4'!$L$5:$L$104,0)),"")<>"","'Pillar 4'!A"&IFERROR(MATCH($K$5,'Pillar 4'!$L$5:$L$104,0)+5-1,0),"'Tuan Buffer'!A"&IFERROR(MATCH($K$5,'Tuan Buffer'!$L$5:$L$104,0)+5-1,0))))) | T6: {=_xlfn.TEXTJOIN("",TRUE,IF('Pillar 1'!$L$5:$L$104=$S$5,"["&'Pillar 1'!$C$5:$C$104&"] "&'Pillar 1'!$B$5:$B$104&CHAR(10),""))} | U6: {=_xlfn.TEXTJOIN("",TRUE,IF('Pillar 2'!$L$5:$L$104=$S$5,"["&'Pillar 2'!$C$5:$C$104&"] "&'Pillar 2'!$B$5:$B$104&CHAR(10),""))} | V6: {=_xlfn.TEXTJOIN("",TRUE,IF('Pillar 3'!$L$5:$L$104=$S$5,"["&'Pillar 3'!$C$5:$C$104&"] "&'Pillar 3'!$B$5:$B$104&CHAR(10),""))} | W6: {=_xlfn.TEXTJOIN("",TRUE,IF('Pillar 4'!$L$5:$L$104=$S$5,"["&'Pillar 4'!$C$5:$C$104&"] "&'Pillar 4'!$B$5:$B$104&CHAR(10),""))} | X6: {=_xlfn.TEXTJOIN("",TRUE,IF('Tuan Buffer'!$L$5:$L$104=$S$5,"["&'Tuan Buffer'!$C$5:$C$104&"] "&'Tuan Buffer'!$B$5:$B$104&CHAR(10),""))} | Y6: =IF(IFERROR(INDEX('Pillar 1'!$C$5:$C$104,MATCH($S$5,'Pillar 1'!$L$5:$L$104,0)),"")<>"",IFERROR(INDEX('Pillar 1'!$C$5:$C$104,MATCH($S$5,'Pillar 1'!$L$5:$L$104,0)),""),IF(IFERROR(INDEX('Pillar 2'!$C$5:$C$104,MATCH($S$5,'Pillar 2'!$L$5:$L$104,0)),"")<>"",IFERROR(INDEX('Pillar 2'!$C$5:$C$104,MATCH($S$5,'Pillar 2'!$L$5:$L$104,0)),""),IF(IFERROR(INDEX('Pillar 3'!$C$5:$C$104,MATCH($S$5,'Pillar 3'!$L$5:$L$104,0)),"")<>"",IFERROR(INDEX('Pillar 3'!$C$5:$C$104,MATCH($S$5,'Pillar 3'!$L$5:$L$104,0)),""),IF(IFERROR(INDEX('Pillar 4'!$C$5:$C$104,MATCH($S$5,'Pillar 4'!$L$5:$L$104,0)),"")<>"",IFERROR(INDEX('Pillar 4'!$C$5:$C$104,MATCH($S$5,'Pillar 4'!$L$5:$L$104,0)),""),IFERROR(INDEX('Tuan Buffer'!$C$5:$C$104,MATCH($S$5,'Tuan Buffer'!$L$5:$L$104,0)),""))))) | Z6: =IF(IFERROR(INDEX('Pillar 1'!$C$5:$C$104,MATCH($S$5,'Pillar 1'!$L$5:$L$104,0)),"")<>"","'Pillar 1'!A"&IFERROR(MATCH($S$5,'Pillar 1'!$L$5:$L$104,0)+5-1,0),IF(IFERROR(INDEX('Pillar 2'!$C$5:$C$104,MATCH($S$5,'Pillar 2'!$L$5:$L$104,0)),"")<>"","'Pillar 2'!A"&IFERROR(MATCH($S$5,'Pillar 2'!$L$5:$L$104,0)+5-1,0),IF(IFERROR(INDEX('Pillar 3'!$C$5:$C$104,MATCH($S$5,'Pillar 3'!$L$5:$L$104,0)),"")<>"","'Pillar 3'!A"&IFERROR(MATCH($S$5,'Pillar 3'!$L$5:$L$104,0)+5-1,0),IF(IFERROR(INDEX('Pillar 4'!$C$5:$C$104,MATCH($S$5,'Pillar 4'!$L$5:$L$104,0)),"")<>"","'Pillar 4'!A"&IFERROR(MATCH($S$5,'Pillar 4'!$L$5:$L$104,0)+5-1,0),"'Tuan Buffer'!A"&IFERROR(MATCH($S$5,'Tuan Buffer'!$L$5:$L$104,0)+5-1,0))))) | AB6: {=_xlfn.TEXTJOIN("",TRUE,IF('Pillar 1'!$L$5:$L$104=$AA$5,"["&'Pillar 1'!$C$5:$C$104&"] "&'Pillar 1'!$B$5:$B$104&CHAR(10),""))} | AC6: {=_xlfn.TEXTJOIN("",TRUE,IF('Pillar 2'!$L$5:$L$104=$AA$5,"["&'Pillar 2'!$C$5:$C$104&"] "&'Pillar 2'!$B$5:$B$104&CHAR(10),""))} | AD6: {=_xlfn.TEXTJOIN("",TRUE,IF('Pillar 3'!$L$5:$L$104=$AA$5,"["&'Pillar 3'!$C$5:$C$104&"] "&'Pillar 3'!$B$5:$B$104&CHAR(10),""))} | AE6: {=_xlfn.TEXTJOIN("",TRUE,IF('Pillar 4'!$L$5:$L$104=$AA$5,"["&'Pillar 4'!$C$5:$C$104&"] "&'Pillar 4'!$B$5:$B$104&CHAR(10),""))} | AF6: {=_xlfn.TEXTJOIN("",TRUE,IF('Tuan Buffer'!$L$5:$L$104=$AA$5,"["&'Tuan Buffer'!$C$5:$C$104&"] "&'Tuan Buffer'!$B$5:$B$104&CHAR(10),""))} | AG6: =IF(IFERROR(INDEX('Pillar 1'!$C$5:$C$104,MATCH($AA$5,'Pillar 1'!$L$5:$L$104,0)),"")<>"",IFERROR(INDEX('Pillar 1'!$C$5:$C$104,MATCH($AA$5,'Pillar 1'!$L$5:$L$104,0)),""),IF(IFERROR(INDEX('Pillar 2'!$C$5:$C$104,MATCH($AA$5,'Pillar 2'!$L$5:$L$104,0)),"")<>"",IFERROR(INDEX('Pillar 2'!$C$5:$C$104,MATCH($AA$5,'Pillar 2'!$L$5:$L$104,0)),""),IF(IFERROR(INDEX('Pillar 3'!$C$5:$C$104,MATCH($AA$5,'Pillar 3'!$L$5:$L$104,0)),"")<>"",IFERROR(INDEX('Pillar 3'!$C$5:$C$104,MATCH($AA$5,'Pillar 3'!$L$5:$L$104,0)),""),IF(IFERROR(INDEX('Pillar 4'!$C$5:$C$104,MATCH($AA$5,'Pillar 4'!$L$5:$L$104,0)),"")<>"",IFERROR(INDEX('Pillar 4'!$C$5:$C$104,MATCH($AA$5,'Pillar 4'!$L$5:$L$104,0)),""),IFERROR(INDEX('Tuan Buffer'!$C$5:$C$104,MATCH($AA$5,'Tuan Buffer'!$L$5:$L$104,0)),""))))) | AH6: =IF(IFERROR(INDEX('Pillar 1'!$C$5:$C$104,MATCH($AA$5,'Pillar 1'!$L$5:$L$104,0)),"")<>"","'Pillar 1'!A"&IFERROR(MATCH($AA$5,'Pillar 1'!$L$5:$L$104,0)+5-1,0),IF(IFERROR(INDEX('Pillar 2'!$C$5:$C$104,MATCH($AA$5,'Pillar 2'!$L$5:$L$104,0)),"")<>"","'Pillar 2'!A"&IFERROR(MATCH($AA$5,'Pillar 2'!$L$5:$L$104,0)+5-1,0),IF(IFERROR(INDEX('Pillar 3'!$C$5:$C$104,MATCH($AA$5,'Pillar 3'!$L$5:$L$104,0)),"")<>"","'Pillar 3'!A"&IFERROR(MATCH($AA$5,'Pillar 3'!$L$5:$L$104,0)+5-1,0),IF(IFERROR(INDEX('Pillar 4'!$C$5:$C$104,MATCH($AA$5,'Pillar 4'!$L$5:$L$104,0)),"")<>"","'Pillar 4'!A"&IFERROR(MATCH($AA$5,'Pillar 4'!$L$5:$L$104,0)+5-1,0),"'Tuan Buffer'!A"&IFERROR(MATCH($AA$5,'Tuan Buffer'!$L$5:$L$104,0)+5-1,0))))) | AJ6: {=_xlfn.TEXTJOIN("",TRUE,IF('Pillar 1'!$L$5:$L$104=$AI$5,"["&'Pillar 1'!$C$5:$C$104&"] "&'Pillar 1'!$B$5:$B$104&CHAR(10),""))} | AK6: {=_xlfn.TEXTJOIN("",TRUE,IF('Pillar 2'!$L$5:$L$104=$AI$5,"["&'Pillar 2'!$C$5:$C$104&"] "&'Pillar 2'!$B$5:$B$104&CHAR(10),""))} | AL6: {=_xlfn.TEXTJOIN("",TRUE,IF('Pillar 3'!$L$5:$L$104=$AI$5,"["&'Pillar 3'!$C$5:$C$104&"] "&'Pillar 3'!$B$5:$B$104&CHAR(10),""))} | AM6: {=_xlfn.TEXTJOIN("",TRUE,IF('Pillar 4'!$L$5:$L$104=$AI$5,"["&'Pillar 4'!$C$5:$C$104&"] "&'Pillar 4'!$B$5:$B$104&CHAR(10),""))} | AN6: {=_xlfn.TEXTJOIN("",TRUE,IF('Tuan Buffer'!$L$5:$L$104=$AI$5,"["&'Tuan Buffer'!$C$5:$C$104&"] "&'Tuan Buffer'!$B$5:$B$104&CHAR(10),""))} | AO6: =IF(IFERROR(INDEX('Pillar 1'!$C$5:$C$104,MATCH($AI$5,'Pillar 1'!$L$5:$L$104,0)),"")<>"",IFERROR(INDEX('Pillar 1'!$C$5:$C$104,MATCH($AI$5,'Pillar 1'!$L$5:$L$104,0)),""),IF(IFERROR(INDEX('Pillar 2'!$C$5:$C$104,MATCH($AI$5,'Pillar 2'!$L$5:$L$104,0)),"")<>"",IFERROR(INDEX('Pillar 2'!$C$5:$C$104,MATCH($AI$5,'Pillar 2'!$L$5:$L$104,0)),""),IF(IFERROR(INDEX('Pillar 3'!$C$5:$C$104,MATCH($AI$5,'Pillar 3'!$L$5:$L$104,0)),"")<>"",IFERROR(INDEX('Pillar 3'!$C$5:$C$104,MATCH($AI$5,'Pillar 3'!$L$5:$L$104,0)),""),IF(IFERROR(INDEX('Pillar 4'!$C$5:$C$104,MATCH($AI$5,'Pillar 4'!$L$5:$L$104,0)),"")<>"",IFERROR(INDEX('Pillar 4'!$C$5:$C$104,MATCH($AI$5,'Pillar 4'!$L$5:$L$104,0)),""),IFERROR(INDEX('Tuan Buffer'!$C$5:$C$104,MATCH($AI$5,'Tuan Buffer'!$L$5:$L$104,0)),""))))) | AP6: =IF(IFERROR(INDEX('Pillar 1'!$C$5:$C$104,MATCH($AI$5,'Pillar 1'!$L$5:$L$104,0)),"")<>"","'Pillar 1'!A"&IFERROR(MATCH($AI$5,'Pillar 1'!$L$5:$L$104,0)+5-1,0),IF(IFERROR(INDEX('Pillar 2'!$C$5:$C$104,MATCH($AI$5,'Pillar 2'!$L$5:$L$104,0)),"")<>"","'Pillar 2'!A"&IFERROR(MATCH($AI$5,'Pillar 2'!$L$5:$L$104,0)+5-1,0),IF(IFERROR(INDEX('Pillar 3'!$C$5:$C$104,MATCH($AI$5,'Pillar 3'!$L$5:$L$104,0)),"")<>"","'Pillar 3'!A"&IFERROR(MATCH($AI$5,'Pillar 3'!$L$5:$L$104,0)+5-1,0),IF(IFERROR(INDEX('Pillar 4'!$C$5:$C$104,MATCH($AI$5,'Pillar 4'!$L$5:$L$104,0)),"")<>"","'Pillar 4'!A"&IFERROR(MATCH($AI$5,'Pillar 4'!$L$5:$L$104,0)+5-1,0),"'Tuan Buffer'!A"&IFERROR(MATCH($AI$5,'Tuan Buffer'!$L$5:$L$104,0)+5-1,0))))) | AR6: {=_xlfn.TEXTJOIN("",TRUE,IF('Pillar 1'!$L$5:$L$104=$AQ$5,"["&'Pillar 1'!$C$5:$C$104&"] "&'Pillar 1'!$B$5:$B$104&CHAR(10),""))} | AS6: {=_xlfn.TEXTJOIN("",TRUE,IF('Pillar 2'!$L$5:$L$104=$AQ$5,"["&'Pillar 2'!$C$5:$C$104&"] "&'Pillar 2'!$B$5:$B$104&CHAR(10),""))} | AT6: {=_xlfn.TEXTJOIN("",TRUE,IF('Pillar 3'!$L$5:$L$104=$AQ$5,"["&'Pillar 3'!$C$5:$C$104&"] "&'Pillar 3'!$B$5:$B$104&CHAR(10),""))} | AU6: {=_xlfn.TEXTJOIN("",TRUE,IF('Pillar 4'!$L$5:$L$104=$AQ$5,"["&'Pillar 4'!$C$5:$C$104&"] "&'Pillar 4'!$B$5:$B$104&CHAR(10),""))} | AV6: {=_xlfn.TEXTJOIN("",TRUE,IF('Tuan Buffer'!$L$5:$L$104=$AQ$5,"["&'Tuan Buffer'!$C$5:$C$104&"] "&'Tuan Buffer'!$B$5:$B$104&CHAR(10),""))} | AW6: =IF(IFERROR(INDEX('Pillar 1'!$C$5:$C$104,MATCH($AQ$5,'Pillar 1'!$L$5:$L$104,0)),"")<>"",IFERROR(INDEX('Pillar 1'!$C$5:$C$104,MATCH($AQ$5,'Pillar 1'!$L$5:$L$104,0)),""),IF(IFERROR(INDEX('Pillar 2'!$C$5:$C$104,MATCH($AQ$5,'Pillar 2'!$L$5:$L$104,0)),"")<>"",IFERROR(INDEX('Pillar 2'!$C$5:$C$104,MATCH($AQ$5,'Pillar 2'!$L$5:$L$104,0)),""),IF(IFERROR(INDEX('Pillar 3'!$C$5:$C$104,MATCH($AQ$5,'Pillar 3'!$L$5:$L$104,0)),"")<>"",IFERROR(INDEX('Pillar 3'!$C$5:$C$104,MATCH($AQ$5,'Pillar 3'!$L$5:$L$104,0)),""),IF(IFERROR(INDEX('Pillar 4'!$C$5:$C$104,MATCH($AQ$5,'Pillar 4'!$L$5:$L$104,0)),"")<>"",IFERROR(INDEX('Pillar 4'!$C$5:$C$104,MATCH($AQ$5,'Pillar 4'!$L$5:$L$104,0)),""),IFERROR(INDEX('Tuan Buffer'!$C$5:$C$104,MATCH($AQ$5,'Tuan Buffer'!$L$5:$L$104,0)),""))))) | AX6: =IF(IFERROR(INDEX('Pillar 1'!$C$5:$C$104,MATCH($AQ$5,'Pillar 1'!$L$5:$L$104,0)),"")<>"","'Pillar 1'!A"&IFERROR(MATCH($AQ$5,'Pillar 1'!$L$5:$L$104,0)+5-1,0),IF(IFERROR(INDEX('Pillar 2'!$C$5:$C$104,MATCH($AQ$5,'Pillar 2'!$L$5:$L$104,0)),"")<>"","'Pillar 2'!A"&IFERROR(MATCH($AQ$5,'Pillar 2'!$L$5:$L$104,0)+5-1,0),IF(IFERROR(INDEX('Pillar 3'!$C$5:$C$104,MATCH($AQ$5,'Pillar 3'!$L$5:$L$104,0)),"")<>"","'Pillar 3'!A"&IFERROR(MATCH($AQ$5,'Pillar 3'!$L$5:$L$104,0)+5-1,0),IF(IFERROR(INDEX('Pillar 4'!$C$5:$C$104,MATCH($AQ$5,'Pillar 4'!$L$5:$L$104,0)),"")<>"","'Pillar 4'!A"&IFERROR(MATCH($AQ$5,'Pillar 4'!$L$5:$L$104,0)+5-1,0),"'Tuan Buffer'!A"&IFERROR(MATCH($AQ$5,'Tuan Buffer'!$L$5:$L$104,0)+5-1,0))))) | AZ6: {=_xlfn.TEXTJOIN("",TRUE,IF('Pillar 1'!$L$5:$L$104=$AY$5,"["&'Pillar 1'!$C$5:$C$104&"] "&'Pillar 1'!$B$5:$B$104&CHAR(10),""))} | BA6: {=_xlfn.TEXTJOIN("",TRUE,IF('Pillar 2'!$L$5:$L$104=$AY$5,"["&'Pillar 2'!$C$5:$C$104&"] "&'Pillar 2'!$B$5:$B$104&CHAR(10),""))} | BB6: {=_xlfn.TEXTJOIN("",TRUE,IF('Pillar 3'!$L$5:$L$104=$AY$5,"["&'Pillar 3'!$C$5:$C$104&"] "&'Pillar 3'!$B$5:$B$104&CHAR(10),""))} | BC6: {=_xlfn.TEXTJOIN("",TRUE,IF('Pillar 4'!$L$5:$L$104=$AY$5,"["&'Pillar 4'!$C$5:$C$104&"] "&'Pillar 4'!$B$5:$B$104&CHAR(10),""))} | BD6: {=_xlfn.TEXTJOIN("",TRUE,IF('Tuan Buffer'!$L$5:$L$104=$AY$5,"["&'Tuan Buffer'!$C$5:$C$104&"] "&'Tuan Buffer'!$B$5:$B$104&CHAR(10),""))} | BE6: =IF(IFERROR(INDEX('Pillar 1'!$C$5:$C$104,MATCH($AY$5,'Pillar 1'!$L$5:$L$104,0)),"")<>"",IFERROR(INDEX('Pillar 1'!$C$5:$C$104,MATCH($AY$5,'Pillar 1'!$L$5:$L$104,0)),""),IF(IFERROR(INDEX('Pillar 2'!$C$5:$C$104,MATCH($AY$5,'Pillar 2'!$L$5:$L$104,0)),"")<>"",IFERROR(INDEX('Pillar 2'!$C$5:$C$104,MATCH($AY$5,'Pillar 2'!$L$5:$L$104,0)),""),IF(IFERROR(INDEX('Pillar 3'!$C$5:$C$104,MATCH($AY$5,'Pillar 3'!$L$5:$L$104,0)),"")<>"",IFERROR(INDEX('Pillar 3'!$C$5:$C$104,MATCH($AY$5,'Pillar 3'!$L$5:$L$104,0)),""),IF(IFERROR(INDEX('Pillar 4'!$C$5:$C$104,MATCH($AY$5,'Pillar 4'!$L$5:$L$104,0)),"")<>"",IFERROR(INDEX('Pillar 4'!$C$5:$C$104,MATCH($AY$5,'Pillar 4'!$L$5:$L$104,0)),""),IFERROR(INDEX('Tuan Buffer'!$C$5:$C$104,MATCH($AY$5,'Tuan Buffer'!$L$5:$L$104,0)),""))))) | BF6: =IF(IFERROR(INDEX('Pillar 1'!$C$5:$C$104,MATCH($AY$5,'Pillar 1'!$L$5:$L$104,0)),"")<>"","'Pillar 1'!A"&IFERROR(MATCH($AY$5,'Pillar 1'!$L$5:$L$104,0)+5-1,0),IF(IFERROR(INDEX('Pillar 2'!$C$5:$C$104,MATCH($AY$5,'Pillar 2'!$L$5:$L$104,0)),"")<>"","'Pillar 2'!A"&IFERROR(MATCH($AY$5,'Pillar 2'!$L$5:$L$104,0)+5-1,0),IF(IFERROR(INDEX('Pillar 3'!$C$5:$C$104,MATCH($AY$5,'Pillar 3'!$L$5:$L$104,0)),"")<>"","'Pillar 3'!A"&IFERROR(MATCH($AY$5,'Pillar 3'!$L$5:$L$104,0)+5-1,0),IF(IFERROR(INDEX('Pillar 4'!$C$5:$C$104,MATCH($AY$5,'Pillar 4'!$L$5:$L$104,0)),"")<>"","'Pillar 4'!A"&IFERROR(MATCH($AY$5,'Pillar 4'!$L$5:$L$104,0)+5-1,0),"'Tuan Buffer'!A"&IFERROR(MATCH($AY$5,'Tuan Buffer'!$L$5:$L$104,0)+5-1,0))))) | BH6: {=_xlfn.TEXTJOIN("",TRUE,IF('Pillar 1'!$L$5:$L$104=$BG$5,"["&'Pillar 1'!$C$5:$C$104&"] "&'Pillar 1'!$B$5:$B$104&CHAR(10),""))} | BI6: {=_xlfn.TEXTJOIN("",TRUE,IF('Pillar 2'!$L$5:$L$104=$BG$5,"["&'Pillar 2'!$C$5:$C$104&"] "&'Pillar 2'!$B$5:$B$104&CHAR(10),""))} | BJ6: {=_xlfn.TEXTJOIN("",TRUE,IF('Pillar 3'!$L$5:$L$104=$BG$5,"["&'Pillar 3'!$C$5:$C$104&"] "&'Pillar 3'!$B$5:$B$104&CHAR(10),""))} | BK6: {=_xlfn.TEXTJOIN("",TRUE,IF('Pillar 4'!$L$5:$L$104=$BG$5,"["&'Pillar 4'!$C$5:$C$104&"] "&'Pillar 4'!$B$5:$B$104&CHAR(10),""))} | BL6: {=_xlfn.TEXTJOIN("",TRUE,IF('Tuan Buffer'!$L$5:$L$104=$BG$5,"["&'Tuan Buffer'!$C$5:$C$104&"] "&'Tuan Buffer'!$B$5:$B$104&CHAR(10),""))} | BM6: =IF(IFERROR(INDEX('Pillar 1'!$C$5:$C$104,MATCH($BG$5,'Pillar 1'!$L$5:$L$104,0)),"")<>"",IFERROR(INDEX('Pillar 1'!$C$5:$C$104,MATCH($BG$5,'Pillar 1'!$L$5:$L$104,0)),""),IF(IFERROR(INDEX('Pillar 2'!$C$5:$C$104,MATCH($BG$5,'Pillar 2'!$L$5:$L$104,0)),"")<>"",IFERROR(INDEX('Pillar 2'!$C$5:$C$104,MATCH($BG$5,'Pillar 2'!$L$5:$L$104,0)),""),IF(IFERROR(INDEX('Pillar 3'!$C$5:$C$104,MATCH($BG$5,'Pillar 3'!$L$5:$L$104,0)),"")<>"",IFERROR(INDEX('Pillar 3'!$C$5:$C$104,MATCH($BG$5,'Pillar 3'!$L$5:$L$104,0)),""),IF(IFERROR(INDEX('Pillar 4'!$C$5:$C$104,MATCH($BG$5,'Pillar 4'!$L$5:$L$104,0)),"")<>"",IFERROR(INDEX('Pillar 4'!$C$5:$C$104,MATCH($BG$5,'Pillar 4'!$L$5:$L$104,0)),""),IFERROR(INDEX('Tuan Buffer'!$C$5:$C$104,MATCH($BG$5,'Tuan Buffer'!$L$5:$L$104,0)),""))))) | BN6: =IF(IFERROR(INDEX('Pillar 1'!$C$5:$C$104,MATCH($BG$5,'Pillar 1'!$L$5:$L$104,0)),"")<>"","'Pillar 1'!A"&IFERROR(MATCH($BG$5,'Pillar 1'!$L$5:$L$104,0)+5-1,0),IF(IFERROR(INDEX('Pillar 2'!$C$5:$C$104,MATCH($BG$5,'Pillar 2'!$L$5:$L$104,0)),"")<>"","'Pillar 2'!A"&IFERROR(MATCH($BG$5,'Pillar 2'!$L$5:$L$104,0)+5-1,0),IF(IFERROR(INDEX('Pillar 3'!$C$5:$C$104,MATCH($BG$5,'Pillar 3'!$L$5:$L$104,0)),"")<>"","'Pillar 3'!A"&IFERROR(MATCH($BG$5,'Pillar 3'!$L$5:$L$104,0)+5-1,0),IF(IFERROR(INDEX('Pillar 4'!$C$5:$C$104,MATCH($BG$5,'Pillar 4'!$L$5:$L$104,0)),"")<>"","'Pillar 4'!A"&IFERROR(MATCH($BG$5,'Pillar 4'!$L$5:$L$104,0)+5-1,0),"'Tuan Buffer'!A"&IFERROR(MATCH($BG$5,'Tuan Buffer'!$L$5:$L$104,0)+5-1,0)))))
A7: TUẦN 3 P3: [Điền tên chủ đề Pillar 3] | B7: 14 | C7: 15 | D7: 16 | E7: 17 | F7: 18 | G7: 19 | H7: 20 | K7: 46279 | S7: 46280 | AA7: 46281 | AI7: 46282 | AQ7: 46283 | AY7: 46284 | BG7: 46285
B8: =IF($Q$8="",TRIM($L$8&$M$8&$N$8&$O$8&$P$8),HYPERLINK("#"&$R$8,TRIM($L$8&$M$8&$N$8&$O$8&$P$8))) | C8: =IF($Y$8="",TRIM($T$8&$U$8&$V$8&$W$8&$X$8),HYPERLINK("#"&$Z$8,TRIM($T$8&$U$8&$V$8&$W$8&$X$8))) | D8: =IF($AG$8="",TRIM($AB$8&$AC$8&$AD$8&$AE$8&$AF$8),HYPERLINK("#"&$AH$8,TRIM($AB$8&$AC$8&$AD$8&$AE$8&$AF$8))) | E8: =IF($AO$8="",TRIM($AJ$8&$AK$8&$AL$8&$AM$8&$AN$8),HYPERLINK("#"&$AP$8,TRIM($AJ$8&$AK$8&$AL$8&$AM$8&$AN$8))) | F8: =IF($AW$8="",TRIM($AR$8&$AS$8&$AT$8&$AU$8&$AV$8),HYPERLINK("#"&$AX$8,TRIM($AR$8&$AS$8&$AT$8&$AU$8&$AV$8))) | G8: =IF($BE$8="",TRIM($AZ$8&$BA$8&$BB$8&$BC$8&$BD$8),HYPERLINK("#"&$BF$8,TRIM($AZ$8&$BA$8&$BB$8&$BC$8&$BD$8))) | H8: =IF($BM$8="",TRIM($BH$8&$BI$8&$BJ$8&$BK$8&$BL$8),HYPERLINK("#"&$BN$8,TRIM($BH$8&$BI$8&$BJ$8&$BK$8&$BL$8))) | L8: {=_xlfn.TEXTJOIN("",TRUE,IF('Pillar 1'!$L$5:$L$104=$K$7,"["&'Pillar 1'!$C$5:$C$104&"] "&'Pillar 1'!$B$5:$B$104&CHAR(10),""))} | M8: {=_xlfn.TEXTJOIN("",TRUE,IF('Pillar 2'!$L$5:$L$104=$K$7,"["&'Pillar 2'!$C$5:$C$104&"] "&'Pillar 2'!$B$5:$B$104&CHAR(10),""))} | N8: {=_xlfn.TEXTJOIN("",TRUE,IF('Pillar 3'!$L$5:$L$104=$K$7,"["&'Pillar 3'!$C$5:$C$104&"] "&'Pillar 3'!$B$5:$B$104&CHAR(10),""))} | O8: {=_xlfn.TEXTJOIN("",TRUE,IF('Pillar 4'!$L$5:$L$104=$K$7,"["&'Pillar 4'!$C$5:$C$104&"] "&'Pillar 4'!$B$5:$B$104&CHAR(10),""))} | P8: {=_xlfn.TEXTJOIN("",TRUE,IF('Tuan Buffer'!$L$5:$L$104=$K$7,"["&'Tuan Buffer'!$C$5:$C$104&"] "&'Tuan Buffer'!$B$5:$B$104&CHAR(10),""))} | Q8: =IF(IFERROR(INDEX('Pillar 1'!$C$5:$C$104,MATCH($K$7,'Pillar 1'!$L$5:$L$104,0)),"")<>"",IFERROR(INDEX('Pillar 1'!$C$5:$C$104,MATCH($K$7,'Pillar 1'!$L$5:$L$104,0)),""),IF(IFERROR(INDEX('Pillar 2'!$C$5:$C$104,MATCH($K$7,'Pillar 2'!$L$5:$L$104,0)),"")<>"",IFERROR(INDEX('Pillar 2'!$C$5:$C$104,MATCH($K$7,'Pillar 2'!$L$5:$L$104,0)),""),IF(IFERROR(INDEX('Pillar 3'!$C$5:$C$104,MATCH($K$7,'Pillar 3'!$L$5:$L$104,0)),"")<>"",IFERROR(INDEX('Pillar 3'!$C$5:$C$104,MATCH($K$7,'Pillar 3'!$L$5:$L$104,0)),""),IF(IFERROR(INDEX('Pillar 4'!$C$5:$C$104,MATCH($K$7,'Pillar 4'!$L$5:$L$104,0)),"")<>"",IFERROR(INDEX('Pillar 4'!$C$5:$C$104,MATCH($K$7,'Pillar 4'!$L$5:$L$104,0)),""),IFERROR(INDEX('Tuan Buffer'!$C$5:$C$104,MATCH($K$7,'Tuan Buffer'!$L$5:$L$104,0)),""))))) | R8: =IF(IFERROR(INDEX('Pillar 1'!$C$5:$C$104,MATCH($K$7,'Pillar 1'!$L$5:$L$104,0)),"")<>"","'Pillar 1'!A"&IFERROR(MATCH($K$7,'Pillar 1'!$L$5:$L$104,0)+5-1,0),IF(IFERROR(INDEX('Pillar 2'!$C$5:$C$104,MATCH($K$7,'Pillar 2'!$L$5:$L$104,0)),"")<>"","'Pillar 2'!A"&IFERROR(MATCH($K$7,'Pillar 2'!$L$5:$L$104,0)+5-1,0),IF(IFERROR(INDEX('Pillar 3'!$C$5:$C$104,MATCH($K$7,'Pillar 3'!$L$5:$L$104,0)),"")<>"","'Pillar 3'!A"&IFERROR(MATCH($K$7,'Pillar 3'!$L$5:$L$104,0)+5-1,0),IF(IFERROR(INDEX('Pillar 4'!$C$5:$C$104,MATCH($K$7,'Pillar 4'!$L$5:$L$104,0)),"")<>"","'Pillar 4'!A"&IFERROR(MATCH($K$7,'Pillar 4'!$L$5:$L$104,0)+5-1,0),"'Tuan Buffer'!A"&IFERROR(MATCH($K$7,'Tuan Buffer'!$L$5:$L$104,0)+5-1,0))))) | T8: {=_xlfn.TEXTJOIN("",TRUE,IF('Pillar 1'!$L$5:$L$104=$S$7,"["&'Pillar 1'!$C$5:$C$104&"] "&'Pillar 1'!$B$5:$B$104&CHAR(10),""))} | U8: {=_xlfn.TEXTJOIN("",TRUE,IF('Pillar 2'!$L$5:$L$104=$S$7,"["&'Pillar 2'!$C$5:$C$104&"] "&'Pillar 2'!$B$5:$B$104&CHAR(10),""))} | V8: {=_xlfn.TEXTJOIN("",TRUE,IF('Pillar 3'!$L$5:$L$104=$S$7,"["&'Pillar 3'!$C$5:$C$104&"] "&'Pillar 3'!$B$5:$B$104&CHAR(10),""))} | W8: {=_xlfn.TEXTJOIN("",TRUE,IF('Pillar 4'!$L$5:$L$104=$S$7,"["&'Pillar 4'!$C$5:$C$104&"] "&'Pillar 4'!$B$5:$B$104&CHAR(10),""))} | X8: {=_xlfn.TEXTJOIN("",TRUE,IF('Tuan Buffer'!$L$5:$L$104=$S$7,"["&'Tuan Buffer'!$C$5:$C$104&"] "&'Tuan Buffer'!$B$5:$B$104&CHAR(10),""))} | Y8: =IF(IFERROR(INDEX('Pillar 1'!$C$5:$C$104,MATCH($S$7,'Pillar 1'!$L$5:$L$104,0)),"")<>"",IFERROR(INDEX('Pillar 1'!$C$5:$C$104,MATCH($S$7,'Pillar 1'!$L$5:$L$104,0)),""),IF(IFERROR(INDEX('Pillar 2'!$C$5:$C$104,MATCH($S$7,'Pillar 2'!$L$5:$L$104,0)),"")<>"",IFERROR(INDEX('Pillar 2'!$C$5:$C$104,MATCH($S$7,'Pillar 2'!$L$5:$L$104,0)),""),IF(IFERROR(INDEX('Pillar 3'!$C$5:$C$104,MATCH($S$7,'Pillar 3'!$L$5:$L$104,0)),"")<>"",IFERROR(INDEX('Pillar 3'!$C$5:$C$104,MATCH($S$7,'Pillar 3'!$L$5:$L$104,0)),""),IF(IFERROR(INDEX('Pillar 4'!$C$5:$C$104,MATCH($S$7,'Pillar 4'!$L$5:$L$104,0)),"")<>"",IFERROR(INDEX('Pillar 4'!$C$5:$C$104,MATCH($S$7,'Pillar 4'!$L$5:$L$104,0)),""),IFERROR(INDEX('Tuan Buffer'!$C$5:$C$104,MATCH($S$7,'Tuan Buffer'!$L$5:$L$104,0)),""))))) | Z8: =IF(IFERROR(INDEX('Pillar 1'!$C$5:$C$104,MATCH($S$7,'Pillar 1'!$L$5:$L$104,0)),"")<>"","'Pillar 1'!A"&IFERROR(MATCH($S$7,'Pillar 1'!$L$5:$L$104,0)+5-1,0),IF(IFERROR(INDEX('Pillar 2'!$C$5:$C$104,MATCH($S$7,'Pillar 2'!$L$5:$L$104,0)),"")<>"","'Pillar 2'!A"&IFERROR(MATCH($S$7,'Pillar 2'!$L$5:$L$104,0)+5-1,0),IF(IFERROR(INDEX('Pillar 3'!$C$5:$C$104,MATCH($S$7,'Pillar 3'!$L$5:$L$104,0)),"")<>"","'Pillar 3'!A"&IFERROR(MATCH($S$7,'Pillar 3'!$L$5:$L$104,0)+5-1,0),IF(IFERROR(INDEX('Pillar 4'!$C$5:$C$104,MATCH($S$7,'Pillar 4'!$L$5:$L$104,0)),"")<>"","'Pillar 4'!A"&IFERROR(MATCH($S$7,'Pillar 4'!$L$5:$L$104,0)+5-1,0),"'Tuan Buffer'!A"&IFERROR(MATCH($S$7,'Tuan Buffer'!$L$5:$L$104,0)+5-1,0))))) | AB8: {=_xlfn.TEXTJOIN("",TRUE,IF('Pillar 1'!$L$5:$L$104=$AA$7,"["&'Pillar 1'!$C$5:$C$104&"] "&'Pillar 1'!$B$5:$B$104&CHAR(10),""))} | AC8: {=_xlfn.TEXTJOIN("",TRUE,IF('Pillar 2'!$L$5:$L$104=$AA$7,"["&'Pillar 2'!$C$5:$C$104&"] "&'Pillar 2'!$B$5:$B$104&CHAR(10),""))} | AD8: {=_xlfn.TEXTJOIN("",TRUE,IF('Pillar 3'!$L$5:$L$104=$AA$7,"["&'Pillar 3'!$C$5:$C$104&"] "&'Pillar 3'!$B$5:$B$104&CHAR(10),""))} | AE8: {=_xlfn.TEXTJOIN("",TRUE,IF('Pillar 4'!$L$5:$L$104=$AA$7,"["&'Pillar 4'!$C$5:$C$104&"] "&'Pillar 4'!$B$5:$B$104&CHAR(10),""))} | AF8: {=_xlfn.TEXTJOIN("",TRUE,IF('Tuan Buffer'!$L$5:$L$104=$AA$7,"["&'Tuan Buffer'!$C$5:$C$104&"] "&'Tuan Buffer'!$B$5:$B$104&CHAR(10),""))} | AG8: =IF(IFERROR(INDEX('Pillar 1'!$C$5:$C$104,MATCH($AA$7,'Pillar 1'!$L$5:$L$104,0)),"")<>"",IFERROR(INDEX('Pillar 1'!$C$5:$C$104,MATCH($AA$7,'Pillar 1'!$L$5:$L$104,0)),""),IF(IFERROR(INDEX('Pillar 2'!$C$5:$C$104,MATCH($AA$7,'Pillar 2'!$L$5:$L$104,0)),"")<>"",IFERROR(INDEX('Pillar 2'!$C$5:$C$104,MATCH($AA$7,'Pillar 2'!$L$5:$L$104,0)),""),IF(IFERROR(INDEX('Pillar 3'!$C$5:$C$104,MATCH($AA$7,'Pillar 3'!$L$5:$L$104,0)),"")<>"",IFERROR(INDEX('Pillar 3'!$C$5:$C$104,MATCH($AA$7,'Pillar 3'!$L$5:$L$104,0)),""),IF(IFERROR(INDEX('Pillar 4'!$C$5:$C$104,MATCH($AA$7,'Pillar 4'!$L$5:$L$104,0)),"")<>"",IFERROR(INDEX('Pillar 4'!$C$5:$C$104,MATCH($AA$7,'Pillar 4'!$L$5:$L$104,0)),""),IFERROR(INDEX('Tuan Buffer'!$C$5:$C$104,MATCH($AA$7,'Tuan Buffer'!$L$5:$L$104,0)),""))))) | AH8: =IF(IFERROR(INDEX('Pillar 1'!$C$5:$C$104,MATCH($AA$7,'Pillar 1'!$L$5:$L$104,0)),"")<>"","'Pillar 1'!A"&IFERROR(MATCH($AA$7,'Pillar 1'!$L$5:$L$104,0)+5-1,0),IF(IFERROR(INDEX('Pillar 2'!$C$5:$C$104,MATCH($AA$7,'Pillar 2'!$L$5:$L$104,0)),"")<>"","'Pillar 2'!A"&IFERROR(MATCH($AA$7,'Pillar 2'!$L$5:$L$104,0)+5-1,0),IF(IFERROR(INDEX('Pillar 3'!$C$5:$C$104,MATCH($AA$7,'Pillar 3'!$L$5:$L$104,0)),"")<>"","'Pillar 3'!A"&IFERROR(MATCH($AA$7,'Pillar 3'!$L$5:$L$104,0)+5-1,0),IF(IFERROR(INDEX('Pillar 4'!$C$5:$C$104,MATCH($AA$7,'Pillar 4'!$L$5:$L$104,0)),"")<>"","'Pillar 4'!A"&IFERROR(MATCH($AA$7,'Pillar 4'!$L$5:$L$104,0)+5-1,0),"'Tuan Buffer'!A"&IFERROR(MATCH($AA$7,'Tuan Buffer'!$L$5:$L$104,0)+5-1,0))))) | AJ8: {=_xlfn.TEXTJOIN("",TRUE,IF('Pillar 1'!$L$5:$L$104=$AI$7,"["&'Pillar 1'!$C$5:$C$104&"] "&'Pillar 1'!$B$5:$B$104&CHAR(10),""))} | AK8: {=_xlfn.TEXTJOIN("",TRUE,IF('Pillar 2'!$L$5:$L$104=$AI$7,"["&'Pillar 2'!$C$5:$C$104&"] "&'Pillar 2'!$B$5:$B$104&CHAR(10),""))} | AL8: {=_xlfn.TEXTJOIN("",TRUE,IF('Pillar 3'!$L$5:$L$104=$AI$7,"["&'Pillar 3'!$C$5:$C$104&"] "&'Pillar 3'!$B$5:$B$104&CHAR(10),""))} | AM8: {=_xlfn.TEXTJOIN("",TRUE,IF('Pillar 4'!$L$5:$L$104=$AI$7,"["&'Pillar 4'!$C$5:$C$104&"] "&'Pillar 4'!$B$5:$B$104&CHAR(10),""))} | AN8: {=_xlfn.TEXTJOIN("",TRUE,IF('Tuan Buffer'!$L$5:$L$104=$AI$7,"["&'Tuan Buffer'!$C$5:$C$104&"] "&'Tuan Buffer'!$B$5:$B$104&CHAR(10),""))} | AO8: =IF(IFERROR(INDEX('Pillar 1'!$C$5:$C$104,MATCH($AI$7,'Pillar 1'!$L$5:$L$104,0)),"")<>"",IFERROR(INDEX('Pillar 1'!$C$5:$C$104,MATCH($AI$7,'Pillar 1'!$L$5:$L$104,0)),""),IF(IFERROR(INDEX('Pillar 2'!$C$5:$C$104,MATCH($AI$7,'Pillar 2'!$L$5:$L$104,0)),"")<>"",IFERROR(INDEX('Pillar 2'!$C$5:$C$104,MATCH($AI$7,'Pillar 2'!$L$5:$L$104,0)),""),IF(IFERROR(INDEX('Pillar 3'!$C$5:$C$104,MATCH($AI$7,'Pillar 3'!$L$5:$L$104,0)),"")<>"",IFERROR(INDEX('Pillar 3'!$C$5:$C$104,MATCH($AI$7,'Pillar 3'!$L$5:$L$104,0)),""),IF(IFERROR(INDEX('Pillar 4'!$C$5:$C$104,MATCH($AI$7,'Pillar 4'!$L$5:$L$104,0)),"")<>"",IFERROR(INDEX('Pillar 4'!$C$5:$C$104,MATCH($AI$7,'Pillar 4'!$L$5:$L$104,0)),""),IFERROR(INDEX('Tuan Buffer'!$C$5:$C$104,MATCH($AI$7,'Tuan Buffer'!$L$5:$L$104,0)),""))))) | AP8: =IF(IFERROR(INDEX('Pillar 1'!$C$5:$C$104,MATCH($AI$7,'Pillar 1'!$L$5:$L$104,0)),"")<>"","'Pillar 1'!A"&IFERROR(MATCH($AI$7,'Pillar 1'!$L$5:$L$104,0)+5-1,0),IF(IFERROR(INDEX('Pillar 2'!$C$5:$C$104,MATCH($AI$7,'Pillar 2'!$L$5:$L$104,0)),"")<>"","'Pillar 2'!A"&IFERROR(MATCH($AI$7,'Pillar 2'!$L$5:$L$104,0)+5-1,0),IF(IFERROR(INDEX('Pillar 3'!$C$5:$C$104,MATCH($AI$7,'Pillar 3'!$L$5:$L$104,0)),"")<>"","'Pillar 3'!A"&IFERROR(MATCH($AI$7,'Pillar 3'!$L$5:$L$104,0)+5-1,0),IF(IFERROR(INDEX('Pillar 4'!$C$5:$C$104,MATCH($AI$7,'Pillar 4'!$L$5:$L$104,0)),"")<>"","'Pillar 4'!A"&IFERROR(MATCH($AI$7,'Pillar 4'!$L$5:$L$104,0)+5-1,0),"'Tuan Buffer'!A"&IFERROR(MATCH($AI$7,'Tuan Buffer'!$L$5:$L$104,0)+5-1,0))))) | AR8: {=_xlfn.TEXTJOIN("",TRUE,IF('Pillar 1'!$L$5:$L$104=$AQ$7,"["&'Pillar 1'!$C$5:$C$104&"] "&'Pillar 1'!$B$5:$B$104&CHAR(10),""))} | AS8: {=_xlfn.TEXTJOIN("",TRUE,IF('Pillar 2'!$L$5:$L$104=$AQ$7,"["&'Pillar 2'!$C$5:$C$104&"] "&'Pillar 2'!$B$5:$B$104&CHAR(10),""))} | AT8: {=_xlfn.TEXTJOIN("",TRUE,IF('Pillar 3'!$L$5:$L$104=$AQ$7,"["&'Pillar 3'!$C$5:$C$104&"] "&'Pillar 3'!$B$5:$B$104&CHAR(10),""))} | AU8: {=_xlfn.TEXTJOIN("",TRUE,IF('Pillar 4'!$L$5:$L$104=$AQ$7,"["&'Pillar 4'!$C$5:$C$104&"] "&'Pillar 4'!$B$5:$B$104&CHAR(10),""))} | AV8: {=_xlfn.TEXTJOIN("",TRUE,IF('Tuan Buffer'!$L$5:$L$104=$AQ$7,"["&'Tuan Buffer'!$C$5:$C$104&"] "&'Tuan Buffer'!$B$5:$B$104&CHAR(10),""))} | AW8: =IF(IFERROR(INDEX('Pillar 1'!$C$5:$C$104,MATCH($AQ$7,'Pillar 1'!$L$5:$L$104,0)),"")<>"",IFERROR(INDEX('Pillar 1'!$C$5:$C$104,MATCH($AQ$7,'Pillar 1'!$L$5:$L$104,0)),""),IF(IFERROR(INDEX('Pillar 2'!$C$5:$C$104,MATCH($AQ$7,'Pillar 2'!$L$5:$L$104,0)),"")<>"",IFERROR(INDEX('Pillar 2'!$C$5:$C$104,MATCH($AQ$7,'Pillar 2'!$L$5:$L$104,0)),""),IF(IFERROR(INDEX('Pillar 3'!$C$5:$C$104,MATCH($AQ$7,'Pillar 3'!$L$5:$L$104,0)),"")<>"",IFERROR(INDEX('Pillar 3'!$C$5:$C$104,MATCH($AQ$7,'Pillar 3'!$L$5:$L$104,0)),""),IF(IFERROR(INDEX('Pillar 4'!$C$5:$C$104,MATCH($AQ$7,'Pillar 4'!$L$5:$L$104,0)),"")<>"",IFERROR(INDEX('Pillar 4'!$C$5:$C$104,MATCH($AQ$7,'Pillar 4'!$L$5:$L$104,0)),""),IFERROR(INDEX('Tuan Buffer'!$C$5:$C$104,MATCH($AQ$7,'Tuan Buffer'!$L$5:$L$104,0)),""))))) | AX8: =IF(IFERROR(INDEX('Pillar 1'!$C$5:$C$104,MATCH($AQ$7,'Pillar 1'!$L$5:$L$104,0)),"")<>"","'Pillar 1'!A"&IFERROR(MATCH($AQ$7,'Pillar 1'!$L$5:$L$104,0)+5-1,0),IF(IFERROR(INDEX('Pillar 2'!$C$5:$C$104,MATCH($AQ$7,'Pillar 2'!$L$5:$L$104,0)),"")<>"","'Pillar 2'!A"&IFERROR(MATCH($AQ$7,'Pillar 2'!$L$5:$L$104,0)+5-1,0),IF(IFERROR(INDEX('Pillar 3'!$C$5:$C$104,MATCH($AQ$7,'Pillar 3'!$L$5:$L$104,0)),"")<>"","'Pillar 3'!A"&IFERROR(MATCH($AQ$7,'Pillar 3'!$L$5:$L$104,0)+5-1,0),IF(IFERROR(INDEX('Pillar 4'!$C$5:$C$104,MATCH($AQ$7,'Pillar 4'!$L$5:$L$104,0)),"")<>"","'Pillar 4'!A"&IFERROR(MATCH($AQ$7,'Pillar 4'!$L$5:$L$104,0)+5-1,0),"'Tuan Buffer'!A"&IFERROR(MATCH($AQ$7,'Tuan Buffer'!$L$5:$L$104,0)+5-1,0))))) | AZ8: {=_xlfn.TEXTJOIN("",TRUE,IF('Pillar 1'!$L$5:$L$104=$AY$7,"["&'Pillar 1'!$C$5:$C$104&"] "&'Pillar 1'!$B$5:$B$104&CHAR(10),""))} | BA8: {=_xlfn.TEXTJOIN("",TRUE,IF('Pillar 2'!$L$5:$L$104=$AY$7,"["&'Pillar 2'!$C$5:$C$104&"] "&'Pillar 2'!$B$5:$B$104&CHAR(10),""))} | BB8: {=_xlfn.TEXTJOIN("",TRUE,IF('Pillar 3'!$L$5:$L$104=$AY$7,"["&'Pillar 3'!$C$5:$C$104&"] "&'Pillar 3'!$B$5:$B$104&CHAR(10),""))} | BC8: {=_xlfn.TEXTJOIN("",TRUE,IF('Pillar 4'!$L$5:$L$104=$AY$7,"["&'Pillar 4'!$C$5:$C$104&"] "&'Pillar 4'!$B$5:$B$104&CHAR(10),""))} | BD8: {=_xlfn.TEXTJOIN("",TRUE,IF('Tuan Buffer'!$L$5:$L$104=$AY$7,"["&'Tuan Buffer'!$C$5:$C$104&"] "&'Tuan Buffer'!$B$5:$B$104&CHAR(10),""))} | BE8: =IF(IFERROR(INDEX('Pillar 1'!$C$5:$C$104,MATCH($AY$7,'Pillar 1'!$L$5:$L$104,0)),"")<>"",IFERROR(INDEX('Pillar 1'!$C$5:$C$104,MATCH($AY$7,'Pillar 1'!$L$5:$L$104,0)),""),IF(IFERROR(INDEX('Pillar 2'!$C$5:$C$104,MATCH($AY$7,'Pillar 2'!$L$5:$L$104,0)),"")<>"",IFERROR(INDEX('Pillar 2'!$C$5:$C$104,MATCH($AY$7,'Pillar 2'!$L$5:$L$104,0)),""),IF(IFERROR(INDEX('Pillar 3'!$C$5:$C$104,MATCH($AY$7,'Pillar 3'!$L$5:$L$104,0)),"")<>"",IFERROR(INDEX('Pillar 3'!$C$5:$C$104,MATCH($AY$7,'Pillar 3'!$L$5:$L$104,0)),""),IF(IFERROR(INDEX('Pillar 4'!$C$5:$C$104,MATCH($AY$7,'Pillar 4'!$L$5:$L$104,0)),"")<>"",IFERROR(INDEX('Pillar 4'!$C$5:$C$104,MATCH($AY$7,'Pillar 4'!$L$5:$L$104,0)),""),IFERROR(INDEX('Tuan Buffer'!$C$5:$C$104,MATCH($AY$7,'Tuan Buffer'!$L$5:$L$104,0)),""))))) | BF8: =IF(IFERROR(INDEX('Pillar 1'!$C$5:$C$104,MATCH($AY$7,'Pillar 1'!$L$5:$L$104,0)),"")<>"","'Pillar 1'!A"&IFERROR(MATCH($AY$7,'Pillar 1'!$L$5:$L$104,0)+5-1,0),IF(IFERROR(INDEX('Pillar 2'!$C$5:$C$104,MATCH($AY$7,'Pillar 2'!$L$5:$L$104,0)),"")<>"","'Pillar 2'!A"&IFERROR(MATCH($AY$7,'Pillar 2'!$L$5:$L$104,0)+5-1,0),IF(IFERROR(INDEX('Pillar 3'!$C$5:$C$104,MATCH($AY$7,'Pillar 3'!$L$5:$L$104,0)),"")<>"","'Pillar 3'!A"&IFERROR(MATCH($AY$7,'Pillar 3'!$L$5:$L$104,0)+5-1,0),IF(IFERROR(INDEX('Pillar 4'!$C$5:$C$104,MATCH($AY$7,'Pillar 4'!$L$5:$L$104,0)),"")<>"","'Pillar 4'!A"&IFERROR(MATCH($AY$7,'Pillar 4'!$L$5:$L$104,0)+5-1,0),"'Tuan Buffer'!A"&IFERROR(MATCH($AY$7,'Tuan Buffer'!$L$5:$L$104,0)+5-1,0))))) | BH8: {=_xlfn.TEXTJOIN("",TRUE,IF('Pillar 1'!$L$5:$L$104=$BG$7,"["&'Pillar 1'!$C$5:$C$104&"] "&'Pillar 1'!$B$5:$B$104&CHAR(10),""))} | BI8: {=_xlfn.TEXTJOIN("",TRUE,IF('Pillar 2'!$L$5:$L$104=$BG$7,"["&'Pillar 2'!$C$5:$C$104&"] "&'Pillar 2'!$B$5:$B$104&CHAR(10),""))} | BJ8: {=_xlfn.TEXTJOIN("",TRUE,IF('Pillar 3'!$L$5:$L$104=$BG$7,"["&'Pillar 3'!$C$5:$C$104&"] "&'Pillar 3'!$B$5:$B$104&CHAR(10),""))} | BK8: {=_xlfn.TEXTJOIN("",TRUE,IF('Pillar 4'!$L$5:$L$104=$BG$7,"["&'Pillar 4'!$C$5:$C$104&"] "&'Pillar 4'!$B$5:$B$104&CHAR(10),""))} | BL8: {=_xlfn.TEXTJOIN("",TRUE,IF('Tuan Buffer'!$L$5:$L$104=$BG$7,"["&'Tuan Buffer'!$C$5:$C$104&"] "&'Tuan Buffer'!$B$5:$B$104&CHAR(10),""))} | BM8: =IF(IFERROR(INDEX('Pillar 1'!$C$5:$C$104,MATCH($BG$7,'Pillar 1'!$L$5:$L$104,0)),"")<>"",IFERROR(INDEX('Pillar 1'!$C$5:$C$104,MATCH($BG$7,'Pillar 1'!$L$5:$L$104,0)),""),IF(IFERROR(INDEX('Pillar 2'!$C$5:$C$104,MATCH($BG$7,'Pillar 2'!$L$5:$L$104,0)),"")<>"",IFERROR(INDEX('Pillar 2'!$C$5:$C$104,MATCH($BG$7,'Pillar 2'!$L$5:$L$104,0)),""),IF(IFERROR(INDEX('Pillar 3'!$C$5:$C$104,MATCH($BG$7,'Pillar 3'!$L$5:$L$104,0)),"")<>"",IFERROR(INDEX('Pillar 3'!$C$5:$C$104,MATCH($BG$7,'Pillar 3'!$L$5:$L$104,0)),""),IF(IFERROR(INDEX('Pillar 4'!$C$5:$C$104,MATCH($BG$7,'Pillar 4'!$L$5:$L$104,0)),"")<>"",IFERROR(INDEX('Pillar 4'!$C$5:$C$104,MATCH($BG$7,'Pillar 4'!$L$5:$L$104,0)),""),IFERROR(INDEX('Tuan Buffer'!$C$5:$C$104,MATCH($BG$7,'Tuan Buffer'!$L$5:$L$104,0)),""))))) | BN8: =IF(IFERROR(INDEX('Pillar 1'!$C$5:$C$104,MATCH($BG$7,'Pillar 1'!$L$5:$L$104,0)),"")<>"","'Pillar 1'!A"&IFERROR(MATCH($BG$7,'Pillar 1'!$L$5:$L$104,0)+5-1,0),IF(IFERROR(INDEX('Pillar 2'!$C$5:$C$104,MATCH($BG$7,'Pillar 2'!$L$5:$L$104,0)),"")<>"","'Pillar 2'!A"&IFERROR(MATCH($BG$7,'Pillar 2'!$L$5:$L$104,0)+5-1,0),IF(IFERROR(INDEX('Pillar 3'!$C$5:$C$104,MATCH($BG$7,'Pillar 3'!$L$5:$L$104,0)),"")<>"","'Pillar 3'!A"&IFERROR(MATCH($BG$7,'Pillar 3'!$L$5:$L$104,0)+5-1,0),IF(IFERROR(INDEX('Pillar 4'!$C$5:$C$104,MATCH($BG$7,'Pillar 4'!$L$5:$L$104,0)),"")<>"","'Pillar 4'!A"&IFERROR(MATCH($BG$7,'Pillar 4'!$L$5:$L$104,0)+5-1,0),"'Tuan Buffer'!A"&IFERROR(MATCH($BG$7,'Tuan Buffer'!$L$5:$L$104,0)+5-1,0)))))
A9: TUẦN 4 P4: [Điền tên chủ đề Pillar 4] | B9: 21 | C9: 22 | D9: 23 | E9: 24 | F9: 25 | G9: 26 | H9: 27 | K9: 46286 | S9: 46287 | AA9: 46288 | AI9: 46289 | AQ9: 46290 | AY9: 46291 | BG9: 46292
